<?xml version="1.0" ?>
<mujoco>
 <worldbody>
  <geom name="floor_maze" type="plane" pos="-9.0 0 -0.05" size="9.0 11.0 0.1" material="floor_mat_maze" condim="1" group="1"/>
  <geom name="wall_maze_0" pos="-17.0 10.0 0.5" size="1.0 1.0 0.5" contype="1" conaffinity="2" class="maze_wall_maze"/>
  <geom name="wall_maze_1" pos="-15.0 10.0 0.5" size="1.0 1.0 0.5" contype="1" conaffinity="2" class="maze_wall_maze"/>
  <geom name="wall_maze_2" pos="-13.0 10.0 0.5" size="1.0 1.0 0.5" contype="1" conaffinity="2" class="maze_wall_maze"/>
  <geom name="wall_maze_3" pos="-11.0 10.0 0.5" size="1.0 1.0 0.5" contype="1" conaffinity="2" class="maze_wall_maze"/>
  <geom name="wall_maze_4" pos="-9.0 10.0 0.5" size="1.0 1.0 0.5" contype="1" conaffinity="2" class="maze_wall_maze"/>
  <geom name="wall_maze_5" pos="-7.0 10.0 0.5" size="1.0 1.0 0.5" contype="1" conaffinity="2" class="maze_wall_maze"/>
  <geom name="wall_maze_6" pos="-5.0 10.0 0.5" size="1.0 1.0 0.5" contype="1" conaffinity="2" class="maze_wall_maze"/>
  <geom name="wall_maze_7" pos="-3.0 10.0 0.5" size="1.0 1.0 0.5" contype="1" conaffinity="2" class="maze_wall_maze"/>
  <geom name="wall_maze_8" pos="-1.0 10.0 0.5" size="1.0 1.0 0.5" contype="1" conaffinity="2" class="maze_wall_maze"/>
  <geom name="wall_maze_9" pos="-17.0 8.0 0.5" size="1.0 1.0 0.5" contype="1" conaffinity="2" class="maze_wall_maze"/>
  <geom name="wall_maze_10" pos="-1.0 8.0 0.5" size="1.0 1.0 0.5" contype="1" conaffinity="2" class="maze_wall_maze"/>
  <geom name="wall_maze_11" pos="-17.0 6.0 0.5" size="1.0 1.0 0.5" contype="1" conaffinity="2" class="maze_wall_maze"/>
  <geom name="wall_maze_12" pos="-1.0 6.0 0.5" size="1.0 1.0 0.5" contype="1" conaffinity="2" class="maze_wall_maze"/>
  <geom name="wall_maze_13" pos="-17.0 4.0 0.5" size="1.0 1.0 0.5" contype="1" conaffinity="2" class="maze_wall_maze"/>
  <geom name="wall_maze_14" pos="-1.0 4.0 0.5" size="1.0 1.0 0.5" contype="1" conaffinity="2" class="maze_wall_maze"/>
  <geom name="wall_maze_15" pos="-17.0 2.0 0.5" size="1.0 1.0 0.5" contype="1" conaffinity="2" class="maze_wall_maze"/>
  <geom name="wall_maze_16" pos="-1.0 2.0 0.5" size="1.0 1.0 0.5" contype="1" conaffinity="2" class="maze_wall_maze"/>
  <geom name="wall_maze_17" pos="-17.0 0.0 0.5" size="1.0 1.0 0.5" contype="1" conaffinity="2" class="maze_wall_maze"/>
  <geom name="wall_maze_18" pos="-1.0 0.0 0.5" size="1.0 1.0 0.5" contype="1" conaffinity="2" class="maze_wall_maze"/>
  <geom name="wall_maze_19" pos="-17.0 -2.0 0.5" size="1.0 1.0 0.5" contype="1" conaffinity="2" class="maze_wall_maze"/>
  <geom name="wall_maze_20" pos="-1.0 -2.0 0.5" size="1.0 1.0 0.5" contype="1" conaffinity="2" class="maze_wall_maze"/>
  <geom name="wall_maze_21" pos="-17.0 -4.0 0.5" size="1.0 1.0 0.5" contype="1" conaffinity="2" class="maze_wall_maze"/>
  <geom name="wall_maze_22" pos="-1.0 -4.0 0.5" size="1.0 1.0 0.5" contype="1" conaffinity="2" class="maze_wall_maze"/>
  <geom name="wall_maze_23" pos="-17.0 -6.0 0.5" size="1.0 1.0 0.5" contype="1" conaffinity="2" class="maze_wall_maze"/>
  <geom name="wall_maze_24" pos="-1.0 -6.0 0.5" size="1.0 1.0 0.5" contype="1" conaffinity="2" class="maze_wall_maze"/>
  <geom name="wall_maze_25" pos="-17.0 -8.0 0.5" size="1.0 1.0 0.5" contype="1" conaffinity="2" class="maze_wall_maze"/>
  <geom name="wall_maze_26" pos="-1.0 -8.0 0.5" size="1.0 1.0 0.5" contype="1" conaffinity="2" class="maze_wall_maze"/>
  <geom name="wall_maze_27" pos="-17.0 -10.0 0.5" size="1.0 1.0 0.5" contype="1" conaffinity="2" class="maze_wall_maze"/>
  <geom name="wall_maze_28" pos="-15.0 -10.0 0.5" size="1.0 1.0 0.5" contype="1" conaffinity="2" class="maze_wall_maze"/>
  <geom name="wall_maze_29" pos="-13.0 -10.0 0.5" size="1.0 1.0 0.5" contype="1" conaffinity="2" class="maze_wall_maze"/>
  <geom name="wall_maze_30" pos="-11.0 -10.0 0.5" size="1.0 1.0 0.5" contype="1" conaffinity="2" class="maze_wall_maze"/>
  <geom name="wall_maze_31" pos="-9.0 -10.0 0.5" size="1.0 1.0 0.5" contype="1" conaffinity="2" class="maze_wall_maze"/>
  <geom name="wall_maze_32" pos="-7.0 -10.0 0.5" size="1.0 1.0 0.5" contype="1" conaffinity="2" class="maze_wall_maze"/>
  <geom name="wall_maze_33" pos="-5.0 -10.0 0.5" size="1.0 1.0 0.5" contype="1" conaffinity="2" class="maze_wall_maze"/>
  <geom name="wall_maze_34" pos="-3.0 -10.0 0.5" size="1.0 1.0 0.5" contype="1" conaffinity="2" class="maze_wall_maze"/>
  <geom name="wall_maze_35" pos="-1.0 -10.0 0.5" size="1.0 1.0 0.5" contype="1" conaffinity="2" class="maze_wall_maze"/>
  <body name="agent_body" pos="0 0 0.2">
   <geom name="agent_geom" type="sphere" size="0.2" rgba="0.0 0.0 1.0 0.01" contype="1" friction=".5 .1 .1" density="1000" margin="0.002" condim="1" conaffinity="1" group="2"/>
   <site name="agent_site" pos="0.0 0.0 0.0" material="agent_mat" size="0.2"/>
   <site name="agent_direction_site" group="2" pos="0.3 0.0 0.0" quat="0.5 0.5 0.5 0.5" type="cylinder" material="agent_direction_mat" rgba="1.0 0.0 0.0 1.0" size="0.05 0.15"/>
   <inertial pos="0 0 0" mass="1" diaginertia="0.1 0.1 0.1"/>
   <joint name="agent_joint_x" type="slide" pos="0 0 0" axis="1 0 0" damping="1" limited="false"/>
   <joint name="agent_joint_y" type="slide" pos="0 0 0" axis="0 1 0" damping="1" limited="false"/>
   <joint name="agent_joint_yaw" type="hinge" pos="0 0 0" axis="0 0 1" damping="1" limited="false"/>
   <camera name="agent_eye" mode="fixed" pos="0.19999999999999984 8.742277968210032e-09 0.0" quat="-0.5000000109278474 -0.5000000109278475 0.4999999890721524 0.49999998907215243" focal="0.01 0.01" sensorsize="0.008284271247461901 0.008284271247461901" resolution="1 1" orthographic="false"/>
   <camera name="agent_eye_0_0" mode="fixed" pos="0.19318516405800687 -0.051763813498243896 0.0" quat="-0.43045932807548165 -0.43045932807548176 0.5609855317856288 0.5609855317856289" focal="0.01 0.01" sensorsize="0.008284271247461901 0.008284271247461901" resolution="32 32" orthographic="false"/>
   <camera name="agent_eye_0_1" mode="fixed" pos="0.19318515953266968 0.05176383038702779 0.0" quat="-0.5609855506016039 -0.5609855506016039 0.43045930355402384 0.4304593035540239" focal="0.01 0.01" sensorsize="0.008284271247461901 0.008284271247461901" resolution="32 32" orthographic="false"/>
  </body>
  <body name="goal0_body" pos="0 0 0.2">
   <geom name="goal0_geom" type="sphere" size="0.2" rgba="0.0 0.0 1.0 0.01" contype="1" friction=".5 .1 .1" density="1000" margin="0.002" condim="1" conaffinity="1" group="2"/>
   <site name="goal0_site" pos="0.0 0.0 0.0" material="goal0_mat" size="0.5" euler="0 0 0"/>
   <site name="goal0_direction_site" group="2" pos="0.3 0.0 0.0" quat="0.5 0.5 0.5 0.5" type="cylinder" material="goal0_direction_mat" rgba="1.0 0.0 0.0 1.0" size="0.05 0.15"/>
   <inertial pos="0 0 0" mass="1" diaginertia="0.1 0.1 0.1"/>
   <joint name="goal0_joint_x" type="slide" pos="0 0 0" axis="1 0 0" damping="1" limited="false"/>
   <joint name="goal0_joint_y" type="slide" pos="0 0 0" axis="0 1 0" damping="1" limited="false"/>
   <joint name="goal0_joint_yaw" type="hinge" pos="0 0 0" axis="0 0 1" damping="1" limited="false"/>
   <site name="goal0_top_site" material="goal0_top_mat" pos="0 0 0.5" size="0.2" group="2"/>
  </body>
  <body name="adversary0_body" pos="0 0 0.2">
   <geom name="adversary0_geom" type="sphere" size="0.2" rgba="0.0 0.0 1.0 0.01" contype="1" friction=".5 .1 .1" density="1000" margin="0.002" condim="1" conaffinity="1" group="2"/>
   <site name="adversary0_site" pos="0.0 0.0 0.0" material="adversary0_mat" size="0.5" euler="0 90 0"/>
   <site name="adversary0_direction_site" group="2" pos="0.3 0.0 0.0" quat="0.5 0.5 0.5 0.5" type="cylinder" material="adversary0_direction_mat" rgba="1.0 0.0 0.0 1.0" size="0.05 0.15"/>
   <inertial pos="0 0 0" mass="1" diaginertia="0.1 0.1 0.1"/>
   <joint name="adversary0_joint_x" type="slide" pos="0 0 0" axis="1 0 0" damping="1" limited="false"/>
   <joint name="adversary0_joint_y" type="slide" pos="0 0 0" axis="0 1 0" damping="1" limited="false"/>
   <joint name="adversary0_joint_yaw" type="hinge" pos="0 0 0" axis="0 0 1" damping="1" limited="false"/>
   <site name="adversary0_top_site" material="adversary0_top_mat" pos="0 0 0.5" size="0.2" group="2"/>
  </body>
 </worldbody>
 <asset>
  <material name="floor_mat_maze" rgba="0.1 0.1 0.1 1.0" shininess="0.0" specular="0.0"/>
  <material name="wall_maze_default_vertical_10_mat" texture="wall_maze_default_vertical_10_tex"/>
  <texture name="wall_maze_default_vertical_10_tex" file="maze_textures/vertical_10.png" gridsize="3 4" gridlayout=".U..LFRB.D.."/>
  <material name="agent_mat" emission="1" rgba="0.3 0.6 0.3 1"/>
  <material name="agent_direction_mat" emission="1" rgba="0.6 0.3 0.3 1"/>
  <material name="goal0_mat" emission="2" rgba="1 1 1 1" texture="goal0_tex"/>
  <material name="goal0_direction_mat" emission="1" rgba="0.6 0.3 0.3 1"/>
  <texture name="goal0_tex" file="object_textures/redblue_vertical_8.png" type="2d"/>
  <material name="goal0_top_mat" emission="2" rgba="0.2 0.8 0.2 1.0"/>
  <material name="adversary0_mat" emission="2" rgba="1 1 1 1" texture="adversary0_tex"/>
  <material name="adversary0_direction_mat" emission="1" rgba="0.6 0.3 0.3 1"/>
  <texture name="adversary0_tex" file="object_textures/redblue_vertical_8.png" type="2d"/>
  <material name="adversary0_top_mat" emission="2" rgba="0.8 0.2 0.2 1.0"/>
 </asset>
 <default>
  <default class="maze_wall_maze">
   <geom type="box" gap="0.05" margin="0.1" group="3" condim="1"/>
  </default>
 </default>
 <include file="cambrian/models/agents/agent.xml"/>
 <option integrator="implicitfast" timestep="0.02">
  <flag frictionloss="disable"/>
 </option>
 <visual>
  <headlight active="0"/>
  <map znear="0.0001" zfar="3"/>
  <scale frustum="20"/>
  <rgba camera="0.6 0.9 0.6 1"/>
  <quality offsamples="0"/>
 </visual>
 <actuator>
  <velocity name="agent_act_x" joint="agent_joint_x" ctrlrange="-10.0 10.0" ctrllimited="true" kv="100"/>
  <velocity name="agent_act_y" joint="agent_joint_y" ctrlrange="-10.0 10.0" ctrllimited="true" kv="100"/>
  <position name="agent_act_yaw" joint="agent_joint_yaw" ctrlrange="-3.14 3.14" ctrllimited="true" gear="1"/>
  <velocity name="goal0_act_x" joint="goal0_joint_x" ctrlrange="-10.0 10.0" ctrllimited="true" kv="100"/>
  <velocity name="goal0_act_y" joint="goal0_joint_y" ctrlrange="-10.0 10.0" ctrllimited="true" kv="100"/>
  <position name="goal0_act_yaw" joint="goal0_joint_yaw" ctrlrange="-3.14 3.14" ctrllimited="true" gear="1"/>
  <velocity name="adversary0_act_x" joint="adversary0_joint_x" ctrlrange="-10.0 10.0" ctrllimited="true" kv="100"/>
  <velocity name="adversary0_act_y" joint="adversary0_joint_y" ctrlrange="-10.0 10.0" ctrllimited="true" kv="100"/>
  <position name="adversary0_act_yaw" joint="adversary0_joint_yaw" ctrlrange="-3.14 3.14" ctrllimited="true" gear="1"/>
 </actuator>
</mujoco>